<?xml version="1.0"?>
<robot xmlns:xacro="http://www.ros.org/wiki/xacro">

  <xacro:macro name="dumbot_base">

    <xacro:property name="PI" value="3.1415926535897931"/>
    <xacro:property name="base_mass" value="0.3"/>
    <xacro:property name="base_width" value="0.4"/>
    <xacro:property name="base_length" value="0.5"/>
    <xacro:property name="base_height" value="0.05"/>

    <xacro:property name="wheel_mass" value="0.3"/>
    <xacro:property name="wheel_len" value="0.050"/>
    <xacro:property name="wheel_radius" value="0.11"/>

    <xacro:property name="caster_wheel_mass" value="0.1"/>
    <xacro:property name="caster_wheel_radius" value="0.1"/>

    <!-- Front/rear wheel x positions -->
    <xacro:property name="front_wheel_x" value="0.0"/>
    <xacro:property name="rear_wheel_x" value="${3*base_length/4}"/>

    <link name="base_footprint" />

    <joint name="base_joint" type="fixed">
      <parent link="base_footprint"/>
      <child link="base_link"/>
      <origin xyz="0 0 ${wheel_radius}" rpy="0 0 0"/>
    </joint>

    <link name="base_link">
      <collision>
        <origin xyz="${3*base_length/8} 0 ${wheel_radius}" rpy="0 0 0"/>
        <geometry>
          <box size="${base_length} ${base_width} ${base_height}"/>
        </geometry>
      </collision>

      <visual>
        <origin xyz="${3*base_length/8} 0 ${wheel_radius}" rpy="0 0 0"/>
        <geometry>
          <box size="${base_length} ${base_width} ${base_height}"/>
        </geometry>
        <material name="orange"/>
      </visual>

      <inertial>
        <origin xyz="0 0 0" rpy="0 0 0"/>
        <mass value="${base_mass}"/>
        <inertia
          ixx="${base_mass / 12.0 * (base_length*base_length + base_height*base_height)}"
          ixy="0.0"
          ixz="0.0"
          iyy="${base_mass / 12.0 * (base_height*base_height + base_width*base_width)}"
          iyz="0.0"
          izz="${base_mass / 12.0 * (base_width*base_width + base_length*base_length)}"/>
      </inertial>
    </link>

    <!-- Front left wheel -->
    <joint name="front_left_wheel_joint" type="continuous">
      <parent link="base_link"/>
      <child link="front_left_wheel"/>
      <origin xyz="${front_wheel_x} ${-base_width/2 - wheel_len/2} 0" rpy="0 0 0"/>
      <axis xyz="0 1 0"/>
      <dynamics damping="0.2"/>
    </joint>

    <link name="front_left_wheel">
      <collision>
        <origin xyz="0 0 0" rpy="${PI/2} 0 0"/>
        <geometry>
          <cylinder length="${wheel_len}" radius="${wheel_radius}"/>
        </geometry>
      </collision>

      <visual>
        <origin xyz="0 0 0" rpy="${PI/2} 0 0"/>
        <geometry>
          <cylinder length="${wheel_len}" radius="${wheel_radius}"/>
        </geometry>
        <material name="black"/>
      </visual>

      <inertial>
        <origin xyz="0 0 0" rpy="${PI/2} 0 0"/>
        <mass value="${wheel_mass}"/>
        <inertia
          ixx="${wheel_mass / 12.0 * (3*wheel_radius*wheel_radius + wheel_len*wheel_len)}"
          ixy="0.0"
          ixz="0.0"
          iyy="${wheel_mass / 2.0 * wheel_radius*wheel_radius}"
          iyz="0.0"
          izz="${wheel_mass / 12.0 * (3*wheel_radius*wheel_radius + wheel_len*wheel_len)}"/>
      </inertial>
    </link>

    <!-- Front right wheel -->
    <joint name="front_right_wheel_joint" type="continuous">
      <parent link="base_link"/>
      <child link="front_right_wheel"/>
      <origin xyz="${front_wheel_x} ${base_width/2 + wheel_len/2} 0" rpy="0 0 0"/>
      <axis xyz="0 1 0"/>
      <dynamics damping="0.2"/>
    </joint>

    <link name="front_right_wheel">
      <collision>
        <origin xyz="0 0 0" rpy="${PI/2} 0 0"/>
        <geometry>
          <cylinder length="${wheel_len}" radius="${wheel_radius}"/>
        </geometry>
      </collision>

      <visual>
        <origin xyz="0 0 0" rpy="${PI/2} 0 0"/>
        <geometry>
          <cylinder length="${wheel_len}" radius="${wheel_radius}"/>
        </geometry>
        <material name="black"/>
      </visual>

      <inertial>
        <origin xyz="0 0 0" rpy="${PI/2} 0 0"/>
        <mass value="${wheel_mass}"/>
        <inertia
          ixx="${wheel_mass / 12.0 * (3*wheel_radius*wheel_radius + wheel_len*wheel_len)}"
          ixy="0.0"
          ixz="0.0"
          iyy="${wheel_mass / 2.0 * wheel_radius*wheel_radius}"
          iyz="0.0"
          izz="${wheel_mass / 12.0 * (3*wheel_radius*wheel_radius + wheel_len*wheel_len)}"/>
      </inertial>
    </link>

    <!-- Rear left wheel -->
    <joint name="rear_left_wheel_joint" type="continuous">
      <parent link="base_link"/>
      <child link="rear_left_wheel"/>
      <origin xyz="${rear_wheel_x} ${-base_width/2 - wheel_len/2} 0" rpy="0 0 0"/>
      <axis xyz="0 1 0"/>
      <dynamics damping="0.2"/>
    </joint>

    <link name="rear_left_wheel">
      <collision>
        <origin xyz="0 0 0" rpy="${PI/2} 0 0"/>
        <geometry>
          <cylinder length="${wheel_len}" radius="${wheel_radius}"/>
        </geometry>
      </collision>

      <visual>
        <origin xyz="0 0 0" rpy="${PI/2} 0 0"/>
        <geometry>
          <cylinder length="${wheel_len}" radius="${wheel_radius}"/>
        </geometry>
        <material name="black"/>
      </visual>

      <inertial>
        <origin xyz="0 0 0" rpy="${PI/2} 0 0"/>
        <mass value="${wheel_mass}"/>
        <inertia
          ixx="${wheel_mass / 12.0 * (3*wheel_radius*wheel_radius + wheel_len*wheel_len)}"
          ixy="0.0"
          ixz="0.0"
          iyy="${wheel_mass / 2.0 * wheel_radius*wheel_radius}"
          iyz="0.0"
          izz="${wheel_mass / 12.0 * (3*wheel_radius*wheel_radius + wheel_len*wheel_len)}"/>
      </inertial>
    </link>

    <!-- Rear right wheel -->
    <joint name="rear_right_wheel_joint" type="continuous">
      <parent link="base_link"/>
      <child link="rear_right_wheel"/>
      <origin xyz="${rear_wheel_x} ${base_width/2 + wheel_len/2} 0" rpy="0 0 0"/>
      <axis xyz="0 1 0"/>
      <dynamics damping="0.2"/>
    </joint>

    <link name="rear_right_wheel">
      <collision>
        <origin xyz="0 0 0" rpy="${PI/2} 0 0"/>
        <geometry>
          <cylinder length="${wheel_len}" radius="${wheel_radius}"/>
        </geometry>
      </collision>

      <visual>
        <origin xyz="0 0 0" rpy="${PI/2} 0 0"/>
        <geometry>
          <cylinder length="${wheel_len}" radius="${wheel_radius}"/>
        </geometry>
        <material name="black"/>
      </visual>

      <inertial>
        <origin xyz="0 0 0" rpy="${PI/2} 0 0"/>
        <mass value="${wheel_mass}"/>
        <inertia
          ixx="${wheel_mass / 12.0 * (3*wheel_radius*wheel_radius + wheel_len*wheel_len)}"
          ixy="0.0"
          ixz="0.0"
          iyy="${wheel_mass / 2.0 * wheel_radius*wheel_radius}"
          iyz="0.0"
          izz="${wheel_mass / 12.0 * (3*wheel_radius*wheel_radius + wheel_len*wheel_len)}"/>
      </inertial>
    </link>

    <!-- Casters -->
    <joint name="caster_left_wheel_joint" type="fixed">
      <parent link="base_link"/>
      <child link="caster_left_wheel"/>
      <origin xyz="${3*base_length/8} ${base_width/2} ${caster_wheel_radius - wheel_radius}" rpy="0 0 0"/>
    </joint>

    <link name="caster_left_wheel">
      <collision>
        <origin xyz="0 0 0" rpy="0 0 0"/>
        <geometry>
          <sphere radius="${caster_wheel_radius}"/>
        </geometry>
      </collision>

      <visual>
        <origin xyz="0 0 0" rpy="0 0 0"/>
        <geometry>
          <sphere radius="${caster_wheel_radius}"/>
        </geometry>
        <material name="white"/>
      </visual>

      <inertial>
        <origin xyz="0 0 0" rpy="0 0 0"/>
        <mass value="${caster_wheel_mass}"/>
        <inertia
          ixx="${caster_wheel_mass * 0.4 * caster_wheel_radius * caster_wheel_radius}"
          ixy="0.0"
          ixz="0.0"
          iyy="${caster_wheel_mass * 0.4 * caster_wheel_radius * caster_wheel_radius}"
          iyz="0.0"
          izz="${caster_wheel_mass * 0.4 * caster_wheel_radius * caster_wheel_radius}"/>
      </inertial>
    </link>

    <joint name="caster_right_wheel_joint" type="fixed">
      <parent link="base_link"/>
      <child link="caster_right_wheel"/>
      <origin xyz="${3*base_length/8} -${base_width/2} ${caster_wheel_radius - wheel_radius}" rpy="0 0 0"/>
    </joint>

    <link name="caster_right_wheel">
      <collision>
        <origin xyz="0 0 0" rpy="0 0 0"/>
        <geometry>
          <sphere radius="${caster_wheel_radius}"/>
        </geometry>
      </collision>

      <visual>
        <origin xyz="0 0 0" rpy="0 0 0"/>
        <geometry>
          <sphere radius="${caster_wheel_radius}"/>
        </geometry>
        <material name="white"/>
      </visual>

      <inertial>
        <origin xyz="0 0 0" rpy="0 0 0"/>
        <mass value="${caster_wheel_mass}"/>
        <inertia
          ixx="${caster_wheel_mass * 0.4 * caster_wheel_radius * caster_wheel_radius}"
          ixy="0.0"
          ixz="0.0"
          iyy="${caster_wheel_mass * 0.4 * caster_wheel_radius * caster_wheel_radius}"
          iyz="0.0"
          izz="${caster_wheel_mass * 0.4 * caster_wheel_radius * caster_wheel_radius}"/>
      </inertial>
    </link>

  </xacro:macro>

</robot>